nan:communication.py 148, __init__ > sibiu.py 17, __init__ > main.py 16, __init__ > main.py 57, <module> : Connection SUCCESS
nan:logger.py 34, append_vehicle > sibiu.py 18, __init__ > main.py 16, __init__ > main.py 57, <module> : vehicle found, starting logging
600665:sibiu.py 20, __init__ > main.py 16, __init__ > main.py 57, <module> : Connection Success
600665:sibiu.py 29, test > sibiu.py 46, run > threading.py 980, _bootstrap_inner > threading.py 937, _bootstrap : performing test
600665:communication.py 235, setmode > sibiu.py 30, test > sibiu.py 46, run > threading.py 980, _bootstrap_inner > threading.py 937, _bootstrap : mode changed to MANUAL
601665:communication.py 227, arm > sibiu.py 32, test > sibiu.py 46, run > threading.py 980, _bootstrap_inner > threading.py 937, _bootstrap : vehicle arm
621133:communication.py 75, get_data > communication.py 89, get_acoustic_position > communication.py 99, read_gps_thread > threading.py 917, run > threading.py 980, _bootstrap_inner > threading.py 937, _bootstrap : Exception occured HTTPConnectionPool(host='192.168.7.1', port=80): Max retries exceeded with url: /api/v1/position/acoustic/filtered (Caused by NewConnectionError('<urllib3.connection.HTTPConnection object at 0x00000265E962D8E0>: Failed to establish a new connection: [WinError 10060] Se produjo un error durante el intento de conexión ya que la parte conectada no respondió adecuadamente tras un periodo de tiempo, o bien se produjo un error en la conexión establecida ya que el host conectado no ha podido responder'))
642748:communication.py 75, get_data > communication.py 92, get_global_position > communication.py 100, read_gps_thread > threading.py 917, run > threading.py 980, _bootstrap_inner > threading.py 937, _bootstrap : Exception occured HTTPConnectionPool(host='192.168.7.1', port=80): Max retries exceeded with url: /api/v1/position/global (Caused by NewConnectionError('<urllib3.connection.HTTPConnection object at 0x00000265E992E5E0>: Failed to establish a new connection: [WinError 10060] Se produjo un error durante el intento de conexión ya que la parte conectada no respondió adecuadamente tras un periodo de tiempo, o bien se produjo un error en la conexión establecida ya que el host conectado no ha podido responder'))
651346:communication.py 75, get_data > communication.py 89, get_acoustic_position > communication.py 99, read_gps_thread > threading.py 917, run > threading.py 980, _bootstrap_inner > threading.py 937, _bootstrap : Exception occured HTTPConnectionPool(host='192.168.7.1', port=80): Max retries exceeded with url: /api/v1/position/acoustic/filtered (Caused by NewConnectionError('<urllib3.connection.HTTPConnection object at 0x00000265E99B3880>: Failed to establish a new connection: [WinError 10060] Se produjo un error durante el intento de conexión ya que la parte conectada no respondió adecuadamente tras un periodo de tiempo, o bien se produjo un error en la conexión establecida ya que el host conectado no ha podido responder'))
655946:communication.py 75, get_data > communication.py 92, get_global_position > communication.py 100, read_gps_thread > threading.py 917, run > threading.py 980, _bootstrap_inner > threading.py 937, _bootstrap : Exception occured HTTPConnectionPool(host='192.168.7.1', port=80): Max retries exceeded with url: /api/v1/position/global (Caused by NewConnectionError('<urllib3.connection.HTTPConnection object at 0x00000265E9993D00>: Failed to establish a new connection: [WinError 10060] Se produjo un error durante el intento de conexión ya que la parte conectada no respondió adecuadamente tras un periodo de tiempo, o bien se produjo un error en la conexión establecida ya que el host conectado no ha podido responder'))
676468:main.py 64, <module> : asked to finish program
676868:main.py 41, check_joy_interrupt > threading.py 917, run > threading.py 980, _bootstrap_inner > threading.py 937, _bootstrap : joy read stopped
676868:sibiu.py 66, raise_exception > sibiu.py 73, close > main.py 48, close > main.py 65, <module> : sibiu closed
677268:communication.py 253, close > communication.py 244, safe_close > main.py 49, close > main.py 65, <module> : comm closed
677371:logger.py 75, save_data > threading.py 917, run > threading.py 980, _bootstrap_inner > threading.py 937, _bootstrap : log save thread closed
701571:communication.py 75, get_data > communication.py 89, get_acoustic_position > communication.py 99, read_gps_thread > threading.py 917, run > threading.py 980, _bootstrap_inner > threading.py 937, _bootstrap : Exception occured HTTPConnectionPool(host='192.168.7.1', port=80): Max retries exceeded with url: /api/v1/position/acoustic/filtered (Caused by NewConnectionError('<urllib3.connection.HTTPConnection object at 0x00000265E99C7220>: Failed to establish a new connection: [WinError 10060] Se produjo un error durante el intento de conexión ya que la parte conectada no respondió adecuadamente tras un periodo de tiempo, o bien se produjo un error en la conexión establecida ya que el host conectado no ha podido responder'))
712961:main.py 51, close > main.py 65, <module> : close finished
712961:communication.py 75, get_data > communication.py 92, get_global_position > communication.py 100, read_gps_thread > threading.py 917, run > threading.py 980, _bootstrap_inner > threading.py 937, _bootstrap : Exception occured HTTPConnectionPool(host='192.168.7.1', port=80): Max retries exceeded with url: /api/v1/position/global (Caused by NewConnectionError('<urllib3.connection.HTTPConnection object at 0x00000265E99F62E0>: Failed to establish a new connection: [WinError 10060] Se produjo un error durante el intento de conexión ya que la parte conectada no respondió adecuadamente tras un periodo de tiempo, o bien se produjo un error en la conexión establecida ya que el host conectado no ha podido responder'))
712961:communication.py 114, read_gps_thread > threading.py 917, run > threading.py 980, _bootstrap_inner > threading.py 937, _bootstrap : gps log closed
