nan:communication.py 104, __init__ > sibiu.py 17, __init__ > main.py 16, __init__ > main.py 57, <module> : Connection SUCCESS
nan:logger.py 34, append_vehicle > sibiu.py 18, __init__ > main.py 16, __init__ > main.py 57, <module> : vehicle found, starting logging
4359724:sibiu.py 20, __init__ > main.py 16, __init__ > main.py 57, <module> : Connection Success
4361724:communication.py 35, get_data > communication.py 49, get_acoustic_position > communication.py 59, read_gps_thread > threading.py 917, run > threading.py 980, _bootstrap_inner > threading.py 937, _bootstrap : Exception occured HTTPSConnectionPool(host='192.168.7.1', port=443): Max retries exceeded with url: /api/v1/position/acoustic/filtered (Caused by NewConnectionError('<urllib3.connection.HTTPSConnection object at 0x0000017F6B0364F0>: Failed to establish a new connection: [WinError 10061] No se puede establecer una conexión ya que el equipo de destino denegó expresamente dicha conexión'))
4364464:communication.py 35, get_data > communication.py 52, get_global_position > communication.py 60, read_gps_thread > threading.py 917, run > threading.py 980, _bootstrap_inner > threading.py 937, _bootstrap : Exception occured HTTPSConnectionPool(host='192.168.7.1', port=443): Max retries exceeded with url: /api/v1/position/global (Caused by NewConnectionError('<urllib3.connection.HTTPSConnection object at 0x0000017F6C2FD250>: Failed to establish a new connection: [WinError 10061] No se puede establecer una conexión ya que el equipo de destino denegó expresamente dicha conexión'))
nan:communication.py 103, __init__ > sibiu.py 17, __init__ > main.py 16, __init__ > main.py 57, <module> : Connection SUCCESS
nan:logger.py 34, append_vehicle > sibiu.py 18, __init__ > main.py 16, __init__ > main.py 57, <module> : vehicle found, starting logging
4392657:sibiu.py 20, __init__ > main.py 16, __init__ > main.py 57, <module> : Connection Success
4394534:communication.py 35, get_data > communication.py 49, get_acoustic_position > communication.py 59, read_gps_thread > threading.py 917, run > threading.py 980, _bootstrap_inner > threading.py 937, _bootstrap : Exception occured HTTPSConnectionPool(host='192.168.7.1', port=443): Max retries exceeded with url: /api/v1/position/acoustic/filtered (Caused by NewConnectionError('<urllib3.connection.HTTPSConnection object at 0x0000028EA7CA62E0>: Failed to establish a new connection: [WinError 10061] No se puede establecer una conexión ya que el equipo de destino denegó expresamente dicha conexión'))
4397334:communication.py 35, get_data > communication.py 52, get_global_position > communication.py 60, read_gps_thread > threading.py 917, run > threading.py 980, _bootstrap_inner > threading.py 937, _bootstrap : Exception occured HTTPSConnectionPool(host='192.168.7.1', port=443): Max retries exceeded with url: /api/v1/position/global (Caused by NewConnectionError('<urllib3.connection.HTTPSConnection object at 0x0000028EA8F705B0>: Failed to establish a new connection: [WinError 10061] No se puede establecer una conexión ya que el equipo de destino denegó expresamente dicha conexión'))
4400529:communication.py 35, get_data > communication.py 49, get_acoustic_position > communication.py 59, read_gps_thread > threading.py 917, run > threading.py 980, _bootstrap_inner > threading.py 937, _bootstrap : Exception occured HTTPSConnectionPool(host='192.168.7.1', port=443): Max retries exceeded with url: /api/v1/position/acoustic/filtered (Caused by NewConnectionError('<urllib3.connection.HTTPSConnection object at 0x0000028EA8FC62B0>: Failed to establish a new connection: [WinError 10061] No se puede establecer una conexión ya que el equipo de destino denegó expresamente dicha conexión'))
4401427:communication.py 35, get_data > communication.py 52, get_global_position > communication.py 60, read_gps_thread > threading.py 917, run > threading.py 980, _bootstrap_inner > threading.py 937, _bootstrap : Exception occured HTTPSConnectionPool(host='192.168.7.1', port=443): Max retries exceeded with url: /api/v1/position/global (Caused by NewConnectionError('<urllib3.connection.HTTPSConnection object at 0x0000028EA940DA90>: Failed to establish a new connection: [WinError 10061] No se puede establecer una conexión ya que el equipo de destino denegó expresamente dicha conexión'))
4402027:communication.py 35, get_data > communication.py 49, get_acoustic_position > communication.py 59, read_gps_thread > threading.py 917, run > threading.py 980, _bootstrap_inner > threading.py 937, _bootstrap : Exception occured HTTPSConnectionPool(host='192.168.7.1', port=443): Max retries exceeded with url: /api/v1/position/acoustic/filtered (Caused by NewConnectionError('<urllib3.connection.HTTPSConnection object at 0x0000028EA943A0D0>: Failed to establish a new connection: [WinError 10061] No se puede establecer una conexión ya que el equipo de destino denegó expresamente dicha conexión'))
4402634:communication.py 35, get_data > communication.py 52, get_global_position > communication.py 60, read_gps_thread > threading.py 917, run > threading.py 980, _bootstrap_inner > threading.py 937, _bootstrap : Exception occured HTTPSConnectionPool(host='192.168.7.1', port=443): Max retries exceeded with url: /api/v1/position/global (Caused by NewConnectionError('<urllib3.connection.HTTPSConnection object at 0x0000028EA943AFD0>: Failed to establish a new connection: [WinError 10061] No se puede establecer una conexión ya que el equipo de destino denegó expresamente dicha conexión'))
4403129:communication.py 35, get_data > communication.py 49, get_acoustic_position > communication.py 59, read_gps_thread > threading.py 917, run > threading.py 980, _bootstrap_inner > threading.py 937, _bootstrap : Exception occured HTTPSConnectionPool(host='192.168.7.1', port=443): Max retries exceeded with url: /api/v1/position/acoustic/filtered (Caused by NewConnectionError('<urllib3.connection.HTTPSConnection object at 0x0000028EA943E370>: Failed to establish a new connection: [WinError 10061] No se puede establecer una conexión ya que el equipo de destino denegó expresamente dicha conexión'))
4403629:communication.py 35, get_data > communication.py 52, get_global_position > communication.py 60, read_gps_thread > threading.py 917, run > threading.py 980, _bootstrap_inner > threading.py 937, _bootstrap : Exception occured HTTPSConnectionPool(host='192.168.7.1', port=443): Max retries exceeded with url: /api/v1/position/global (Caused by NewConnectionError('<urllib3.connection.HTTPSConnection object at 0x0000028EA9412160>: Failed to establish a new connection: [WinError 10061] No se puede establecer una conexión ya que el equipo de destino denegó expresamente dicha conexión'))
4405229:communication.py 35, get_data > communication.py 49, get_acoustic_position > communication.py 59, read_gps_thread > threading.py 917, run > threading.py 980, _bootstrap_inner > threading.py 937, _bootstrap : Exception occured HTTPSConnectionPool(host='192.168.7.1', port=443): Max retries exceeded with url: /api/v1/position/acoustic/filtered (Caused by NewConnectionError('<urllib3.connection.HTTPSConnection object at 0x0000028EA943E190>: Failed to establish a new connection: [WinError 10061] No se puede establecer una conexión ya que el equipo de destino denegó expresamente dicha conexión'))
4405934:communication.py 35, get_data > communication.py 52, get_global_position > communication.py 60, read_gps_thread > threading.py 917, run > threading.py 980, _bootstrap_inner > threading.py 937, _bootstrap : Exception occured HTTPSConnectionPool(host='192.168.7.1', port=443): Max retries exceeded with url: /api/v1/position/global (Caused by NewConnectionError('<urllib3.connection.HTTPSConnection object at 0x0000028EA943AFA0>: Failed to establish a new connection: [WinError 10061] No se puede establecer una conexión ya que el equipo de destino denegó expresamente dicha conexión'))
4406829:communication.py 35, get_data > communication.py 49, get_acoustic_position > communication.py 59, read_gps_thread > threading.py 917, run > threading.py 980, _bootstrap_inner > threading.py 937, _bootstrap : Exception occured HTTPSConnectionPool(host='192.168.7.1', port=443): Max retries exceeded with url: /api/v1/position/acoustic/filtered (Caused by NewConnectionError('<urllib3.connection.HTTPSConnection object at 0x0000028EA8FC61F0>: Failed to establish a new connection: [WinError 10061] No se puede establecer una conexión ya que el equipo de destino denegó expresamente dicha conexión'))
4407229:main.py 33, check_joy_interrupt > threading.py 917, run > threading.py 980, _bootstrap_inner > threading.py 937, _bootstrap : asked to close program
4407427:sibiu.py 64, raise_exception > sibiu.py 69, close > main.py 48, close > main.py 34, check_joy_interrupt > threading.py 917, run > threading.py 980, _bootstrap_inner > threading.py 937, _bootstrap : sibiu closed
4407432:communication.py 195, close > communication.py 186, safe_close > main.py 49, close > main.py 34, check_joy_interrupt > threading.py 917, run > threading.py 980, _bootstrap_inner > threading.py 937, _bootstrap : comm closed
4407629:main.py 51, close > main.py 34, check_joy_interrupt > threading.py 917, run > threading.py 980, _bootstrap_inner > threading.py 937, _bootstrap : close finished
4407729:main.py 41, check_joy_interrupt > threading.py 917, run > threading.py 980, _bootstrap_inner > threading.py 937, _bootstrap : joy read stopped
4407734:logger.py 75, save_data > threading.py 917, run > threading.py 980, _bootstrap_inner > threading.py 937, _bootstrap : log save thread closed
4408029:communication.py 35, get_data > communication.py 52, get_global_position > communication.py 60, read_gps_thread > threading.py 917, run > threading.py 980, _bootstrap_inner > threading.py 937, _bootstrap : Exception occured HTTPSConnectionPool(host='192.168.7.1', port=443): Max retries exceeded with url: /api/v1/position/global (Caused by NewConnectionError('<urllib3.connection.HTTPSConnection object at 0x0000028EA9408E80>: Failed to establish a new connection: [WinError 10061] No se puede establecer una conexión ya que el equipo de destino denegó expresamente dicha conexión'))
4408234:communication.py 71, read_gps_thread > threading.py 917, run > threading.py 980, _bootstrap_inner > threading.py 937, _bootstrap : gps log closed
