nan:communication.py 148, __init__ > sibiu.py 17, __init__ > main.py 16, __init__ > main.py 57, <module> : Connection SUCCESS
nan:logger.py 34, append_vehicle > sibiu.py 18, __init__ > main.py 16, __init__ > main.py 57, <module> : vehicle found, starting logging
247613:sibiu.py 20, __init__ > main.py 16, __init__ > main.py 57, <module> : Connection Success
247613:sibiu.py 29, test > sibiu.py 46, run > threading.py 980, _bootstrap_inner > threading.py 937, _bootstrap : performing test
248613:communication.py 235, setmode > sibiu.py 30, test > sibiu.py 46, run > threading.py 980, _bootstrap_inner > threading.py 937, _bootstrap : mode changed to MANUAL
248613:communication.py 227, arm > sibiu.py 32, test > sibiu.py 46, run > threading.py 980, _bootstrap_inner > threading.py 937, _bootstrap : vehicle arm
267180:communication.py 75, get_data > communication.py 89, get_acoustic_position > communication.py 99, read_gps_thread > threading.py 917, run > threading.py 980, _bootstrap_inner > threading.py 937, _bootstrap : Exception occured HTTPConnectionPool(host='192.168.7.1', port=80): Max retries exceeded with url: /api/v1/position/acoustic/filtered (Caused by NewConnectionError('<urllib3.connection.HTTPConnection object at 0x000001E263D565B0>: Failed to establish a new connection: [WinError 10060] Se produjo un error durante el intento de conexión ya que la parte conectada no respondió adecuadamente tras un periodo de tiempo, o bien se produjo un error en la conexión establecida ya que el host conectado no ha podido responder'))
282384:communication.py 75, get_data > communication.py 92, get_global_position > communication.py 100, read_gps_thread > threading.py 917, run > threading.py 980, _bootstrap_inner > threading.py 937, _bootstrap : Exception occured HTTPConnectionPool(host='192.168.7.1', port=80): Max retries exceeded with url: /api/v1/position/global (Caused by NewConnectionError('<urllib3.connection.HTTPConnection object at 0x000001E264281C70>: Failed to establish a new connection: [WinError 10060] Se produjo un error durante el intento de conexión ya que la parte conectada no respondió adecuadamente tras un periodo de tiempo, o bien se produjo un error en la conexión establecida ya que el host conectado no ha podido responder'))
293828:communication.py 75, get_data > communication.py 89, get_acoustic_position > communication.py 99, read_gps_thread > threading.py 917, run > threading.py 980, _bootstrap_inner > threading.py 937, _bootstrap : Exception occured HTTPConnectionPool(host='192.168.7.1', port=80): Max retries exceeded with url: /api/v1/position/acoustic/filtered (Caused by NewConnectionError('<urllib3.connection.HTTPConnection object at 0x000001E2642FF8E0>: Failed to establish a new connection: [WinError 10060] Se produjo un error durante el intento de conexión ya que la parte conectada no respondió adecuadamente tras un periodo de tiempo, o bien se produjo un error en la conexión establecida ya que el host conectado no ha podido responder'))
301300:main.py 64, <module> : asked to finish program
301400:main.py 41, check_joy_interrupt > threading.py 917, run > threading.py 980, _bootstrap_inner > threading.py 937, _bootstrap : joy read stopped
301400:sibiu.py 66, raise_exception > sibiu.py 73, close > main.py 48, close > main.py 65, <module> : sibiu closed
301800:logger.py 75, save_data > threading.py 917, run > threading.py 980, _bootstrap_inner > threading.py 937, _bootstrap : log save thread closed
319503:communication.py 75, get_data > communication.py 92, get_global_position > communication.py 100, read_gps_thread > threading.py 917, run > threading.py 980, _bootstrap_inner > threading.py 937, _bootstrap : Exception occured HTTPConnectionPool(host='192.168.7.1', port=80): Max retries exceeded with url: /api/v1/position/global (Caused by NewConnectionError('<urllib3.connection.HTTPConnection object at 0x000001E2642FFEB0>: Failed to establish a new connection: [WinError 10060] Se produjo un error durante el intento de conexión ya que la parte conectada no respondió adecuadamente tras un periodo de tiempo, o bien se produjo un error en la conexión establecida ya que el host conectado no ha podido responder'))
319600:communication.py 114, read_gps_thread > threading.py 917, run > threading.py 980, _bootstrap_inner > threading.py 937, _bootstrap : gps log closed
