nan:communication.py 148, __init__ > sibiu.py 17, __init__ > main.py 16, __init__ > main.py 57, <module> : Connection SUCCESS
nan:logger.py 34, append_vehicle > sibiu.py 18, __init__ > main.py 16, __init__ > main.py 57, <module> : vehicle found, starting logging
1476729:sibiu.py 20, __init__ > main.py 16, __init__ > main.py 57, <module> : Connection Success
1476729:sibiu.py 29, test > sibiu.py 46, run > threading.py 980, _bootstrap_inner > threading.py 937, _bootstrap : performing test
1477729:communication.py 242, setmode > sibiu.py 30, test > sibiu.py 46, run > threading.py 980, _bootstrap_inner > threading.py 937, _bootstrap : mode changed to MANUAL
1477729:communication.py 234, arm > sibiu.py 32, test > sibiu.py 46, run > threading.py 980, _bootstrap_inner > threading.py 937, _bootstrap : vehicle arm
1496501:communication.py 75, get_data > communication.py 89, get_acoustic_position > communication.py 99, read_gps_thread > threading.py 917, run > threading.py 980, _bootstrap_inner > threading.py 937, _bootstrap : Exception occured HTTPConnectionPool(host='192.168.7.1', port=80): Max retries exceeded with url: /api/v1/position/acoustic/filtered (Caused by NewConnectionError('<urllib3.connection.HTTPConnection object at 0x0000019482F00580>: Failed to establish a new connection: [WinError 10060] Se produjo un error durante el intento de conexión ya que la parte conectada no respondió adecuadamente tras un periodo de tiempo, o bien se produjo un error en la conexión establecida ya que el host conectado no ha podido responder'))
1518924:communication.py 75, get_data > communication.py 92, get_global_position > communication.py 100, read_gps_thread > threading.py 917, run > threading.py 980, _bootstrap_inner > threading.py 937, _bootstrap : Exception occured HTTPConnectionPool(host='192.168.7.1', port=80): Max retries exceeded with url: /api/v1/position/global (Caused by NewConnectionError('<urllib3.connection.HTTPConnection object at 0x0000019483615760>: Failed to establish a new connection: [WinError 10060] Se produjo un error durante el intento de conexión ya que la parte conectada no respondió adecuadamente tras un periodo de tiempo, o bien se produjo un error en la conexión establecida ya que el host conectado no ha podido responder'))
1530419:communication.py 75, get_data > communication.py 89, get_acoustic_position > communication.py 99, read_gps_thread > threading.py 917, run > threading.py 980, _bootstrap_inner > threading.py 937, _bootstrap : Exception occured HTTPConnectionPool(host='192.168.7.1', port=80): Max retries exceeded with url: /api/v1/position/acoustic/filtered (Caused by NewConnectionError('<urllib3.connection.HTTPConnection object at 0x0000019483694310>: Failed to establish a new connection: [WinError 10060] Se produjo un error durante el intento de conexión ya que la parte conectada no respondió adecuadamente tras un periodo de tiempo, o bien se produjo un error en la conexión establecida ya que el host conectado no ha podido responder'))
1540221:main.py 33, check_joy_interrupt > threading.py 917, run > threading.py 980, _bootstrap_inner > threading.py 937, _bootstrap : asked to close program
1540518:sibiu.py 66, raise_exception > sibiu.py 73, close > main.py 48, close > main.py 34, check_joy_interrupt > threading.py 917, run > threading.py 980, _bootstrap_inner > threading.py 937, _bootstrap : sibiu closed
1540619:logger.py 75, save_data > threading.py 917, run > threading.py 980, _bootstrap_inner > threading.py 937, _bootstrap : log save thread closed
1540619:communication.py 260, close > communication.py 251, safe_close > main.py 49, close > main.py 34, check_joy_interrupt > threading.py 917, run > threading.py 980, _bootstrap_inner > threading.py 937, _bootstrap : comm closed
1543308:communication.py 75, get_data > communication.py 92, get_global_position > communication.py 100, read_gps_thread > threading.py 917, run > threading.py 980, _bootstrap_inner > threading.py 937, _bootstrap : Exception occured HTTPConnectionPool(host='192.168.7.1', port=80): Max retries exceeded with url: /api/v1/position/global (Caused by NewConnectionError('<urllib3.connection.HTTPConnection object at 0x00000194836E98E0>: Failed to establish a new connection: [WinError 10060] Se produjo un error durante el intento de conexión ya que la parte conectada no respondió adecuadamente tras un periodo de tiempo, o bien se produjo un error en la conexión establecida ya que el host conectado no ha podido responder'))
1544051:communication.py 114, read_gps_thread > threading.py 917, run > threading.py 980, _bootstrap_inner > threading.py 937, _bootstrap : gps log closed
