nan:communication.py 148, __init__ > sibiu.py 17, __init__ > main.py 16, __init__ > main.py 57, <module> : Connection SUCCESS
nan:logger.py 34, append_vehicle > sibiu.py 18, __init__ > main.py 16, __init__ > main.py 57, <module> : vehicle found, starting logging
161645:sibiu.py 20, __init__ > main.py 16, __init__ > main.py 57, <module> : Connection Success
161645:sibiu.py 29, test > sibiu.py 46, run > threading.py 980, _bootstrap_inner > threading.py 937, _bootstrap : performing test
161645:communication.py 235, setmode > sibiu.py 30, test > sibiu.py 46, run > threading.py 980, _bootstrap_inner > threading.py 937, _bootstrap : mode changed to MANUAL
162645:communication.py 227, arm > sibiu.py 32, test > sibiu.py 46, run > threading.py 980, _bootstrap_inner > threading.py 937, _bootstrap : vehicle arm
164640:logger.py 86, sys_read > __init__.py 1531, notify_message_listeners > __init__.py 1053, listener > mavlink.py 240, mavlink_thread_in > threading.py 917, run > threading.py 980, _bootstrap_inner > threading.py 937, _bootstrap : vehicle was armed
178895:main.py 64, <module> : asked to finish program
178900:sibiu.py 66, raise_exception > sibiu.py 73, close > main.py 48, close > main.py 65, <module> : sibiu closed
178900:main.py 41, check_joy_interrupt > threading.py 917, run > threading.py 980, _bootstrap_inner > threading.py 937, _bootstrap : joy read stopped
179295:communication.py 253, close > communication.py 244, safe_close > main.py 49, close > main.py 65, <module> : comm closed
180900:main.py 51, close > main.py 65, <module> : close finished
180900:logger.py 75, save_data > threading.py 917, run > threading.py 980, _bootstrap_inner > threading.py 937, _bootstrap : log save thread closed
180900:communication.py 75, get_data > communication.py 89, get_acoustic_position > communication.py 99, read_gps_thread > threading.py 917, run > threading.py 980, _bootstrap_inner > threading.py 937, _bootstrap : Exception occured HTTPConnectionPool(host='192.168.7.1', port=80): Max retries exceeded with url: /api/v1/position/acoustic/filtered (Caused by NewConnectionError('<urllib3.connection.HTTPConnection object at 0x0000021751165D90>: Failed to establish a new connection: [WinError 10060] Se produjo un error durante el intento de conexión ya que la parte conectada no respondió adecuadamente tras un periodo de tiempo, o bien se produjo un error en la conexión establecida ya que el host conectado no ha podido responder'))
180900:communication.py 75, get_data > communication.py 92, get_global_position > communication.py 100, read_gps_thread > threading.py 917, run > threading.py 980, _bootstrap_inner > threading.py 937, _bootstrap : Exception occured HTTPConnectionPool(host='192.168.7.1', port=80): Max retries exceeded with url: /api/v1/position/global (Caused by NewConnectionError('<urllib3.connection.HTTPConnection object at 0x000002172ED98C40>: Failed to establish a new connection: [WinError 10060] Se produjo un error durante el intento de conexión ya que la parte conectada no respondió adecuadamente tras un periodo de tiempo, o bien se produjo un error en la conexión establecida ya que el host conectado no ha podido responder'))
180900:communication.py 114, read_gps_thread > threading.py 917, run > threading.py 980, _bootstrap_inner > threading.py 937, _bootstrap : gps log closed
